updated 140367242880768
density updated 140367234488064
updated 140367242880768
updated 140367242880768
updated 140367242880768
stopping threads
threads stopped
Changed dataset
threads starting
updated 140367242880768
density updated 140367234488064
threads running
threads restarted
Exception in thread Thread-4:
Traceback (most recent call last):
  File "/usr/lib/python3.8/threading.py", line 932, in _bootstrap_inner
    self.run()
  File "/usr/lib/python3.8/threading.py", line 870, in run
    self._target(*self._args, **self._kwargs)
  File "/home/digiadmin/Documents/code/space_junk_tracker/main.py", line 96, in density_update
    self.point_cloud['point_color'][:] = self.densities
  File "/usr/local/lib/python3.8/dist-packages/pyvista/core/pyvista_ndarray.py", line 66, in __setitem__
    super().__setitem__(key, value)
ValueError: could not broadcast input array from shape (52,) into shape (299,)
updated 140367242880768
Segmentation fault (core dumped)


updated 140137361684224
density updated 140137353291520
updated 140137361684224
updated 140137361684224
updated 140137361684224
density updated 140137353291520
stopping threads
threads stopped
Changed dataset
threads starting
updated 140137353291520
density updated 140137361684224
threads running
threads restarted
Exception in thread Thread-4:
Traceback (most recent call last):
  File "/usr/lib/python3.8/threading.py", line 932, in _bootstrap_inner
    self.run()
  File "/usr/lib/python3.8/threading.py", line 870, in run
    self._target(*self._args, **self._kwargs)
  File "/home/digiadmin/Documents/code/space_junk_tracker/main.py", line 96, in density_update
    self.point_cloud['point_color'][:] = self.densities
  File "/usr/local/lib/python3.8/dist-packages/pyvista/core/pyvista_ndarray.py", line 66, in __setitem__
    super().__setitem__(key, value)
ValueError: could not broadcast input array from shape (52,) into shape (299,)
updated 140137353291520
updated 140137353291520
updated 140137353291520
double free or corruption (out)
Aborted (core dumped)


updated 139694208734976
density updated 139694200342272
updated 139694208734976
updated 139694208734976
updated 139694208734976
stopping threads
threads stopped
Changed dataset
threads starting
updated 139694208734976
density updated 139694200342272
threads running
threads restarted
Segmentation fault (core dumped)


updated 139710999791360
density updated 139710789842688
updated 139710999791360
updated 139710999791360
stopping threads
threads stopped
Changed dataset
threads starting
updated 139710789842688
density updated 139710999791360
threads running
threads restarted
Exception in thread Thread-4:
Traceback (most recent call last):
  File "/usr/lib/python3.8/threading.py", line 932, in _bootstrap_inner
    self.run()
  File "/usr/lib/python3.8/threading.py", line 870, in run
    self._target(*self._args, **self._kwargs)
  File "/home/digiadmin/Documents/code/space_junk_tracker/main.py", line 96, in density_update
    self.point_cloud['point_color'][:] = self.densities
  File "/usr/local/lib/python3.8/dist-packages/pyvista/core/pyvista_ndarray.py", line 66, in __setitem__
    super().__setitem__(key, value)
ValueError: could not broadcast input array from shape (52,) into shape (299,)
corrupted double-linked list
Aborted (core dumped)